Workbook

Sheet Historical Data
A1: INCOME STATEMENT | H1: % on sale
A2: ITEMS | B2: 2021 | C2: 2022 | D2: 2023 | E2: 2024 | F2: 2025 | H2: 2021 | I2: 2022 | J2: 2023 | K2: 2024 | L2: 2025 | M2: Average | P2: CAGR | Q2: =(F3/B3)^(1/4)-1 -> 0.28509315
A3: Net revenue | B3: =SUM(B4:B6) -> 3995471964670 | C3: =SUM(C4:C6) -> 5431604613820 | D3: =SUM(D4:D6) -> 5804412484923 | E3: =SUM(E4:E6) -> 9288059307546 | F3: =SUM(F4:F6) -> 10896989276040 | I3: =(C3-B3)/B3 -> 0.35944005 | J3: =(D3-C3)/C3 -> 0.068636784 | K3: =(E3-D3)/D3 -> 0.60017217 | L3: =(F3-E3)/E3 -> 0.17322563
A4: Drilling services | B4: 1837734722430 | C4: 3535403580588 | D4: 4067897158962 | E4: 5635320312015 | F4: 6052017310330 | H4: =B4/B3 -> 0.45995435 | I4: =C4/C3 -> 0.65089487 | J4: =D4/D3 -> 0.70082841 | K4: =E4/E3 -> 0.60672743 | L4: =F4/F3 -> 0.55538435
A5: Trading | B5: 495288090110 | C5: 114863242736 | D5: 157142368266 | E5: 1207086301149 | F5: 617651216604 | H5: =B5/B3 -> 0.12396235 | I5: =C5/C3 -> 0.021147203 | J5: =D5/D3 -> 0.027072915 | K5: =E5/E3 -> 0.12996109 | L5: =F5/F3 -> 0.056680905 | T5: Net revenue
A6: Other services | B6: 1662449152130 | C6: 1781337790496 | D6: 1579372957695 | E6: 2445652694382 | F6: 4227320749106 | H6: =B6/B3 -> 0.4160833 | I6: =C6/C3 -> 0.32795793 | J6: =D6/D3 -> 0.27209868 | K6: =E6/E3 -> 0.26331149 | L6: =F6/F3 -> 0.38793474 | T6: Drilling services | U6: 0.55538435
A7: Cost of sales | B7: =SUM(B8:B10) -> 3624231518305 | C7: =SUM(C8:C10) -> 4854177283428 | D7: =SUM(D8:D10) -> 4498918879611 | E7: =SUM(E8:E10) -> 7533882511644 | F7: =SUM(F8:F10) -> 8819108718862 | H7: =B7/B3 -> 0.90708471 | I7: =C7/C3 -> 0.89369121 | J7: =D7/D3 -> 0.775086 | K7: =E7/E3 -> 0.81113635 | L7: =F7/F3 -> 0.80931609 | M7: =AVERAGE(H7:L7) -> 0.83926287 | T7: Trading | U7: 0.056680905
A8: Drilling services | B8: 1835180033970 | C8: 3408806370904 | D8: 3204407818170 | E8: 4425686255586 | F8: 4847519368672 | T8: Other services | U8: 0.38793474
A9: Trading | B9: 463541343165 | C9: 86903506360 | D9: 144759187677 | E9: 1163229831462 | F9: 573801413642
A10: Other services | B10: 1325510141170 | C10: 1358467406164 | D10: 1149751873764 | E10: 1944966424596 | F10: 3397787936548
A11: Gross profit | B11: =SUM(B12:B14) -> 371240446365 | C11: =SUM(C12:C14) -> 577427330392 | D11: =SUM(D12:D14) -> 1305493605312 | E11: =SUM(E12:E14) -> 1754176795902 | F11: =SUM(F12:F14) -> 2077880557178 | H11: =B11/B3 -> 0.092915293 | I11: =C11/C3 -> 0.10630879 | J11: =D11/D3 -> 0.224914 | K11: =E11/E3 -> 0.18886365 | L11: =F11/F3 -> 0.19068391 | M11: =AVERAGE(H11:L11) -> 0.16073713
A12: Drilling services | B12: 2554688460 | C12: 126597209684 | D12: 863489340792 | E12: 1209634056429 | F12: 1204497941658
A13: Trading | B13: 31746746945 | C13: 27959736376 | D13: 12383180589 | E13: 43856469687 | F13: 43849802962
A14: Other services | B14: 336939010960 | C14: 422870384332 | D14: 429621083931 | E14: 500686269786 | F14: 829532812558
A15: SG&A | B15: 398535076195 | C15: 510422010912 | D15: 546664325649 | E15: 635219085186 | F15: 854998891466 | H15: =B15/B3 -> 0.099746683 | I15: =C15/C3 -> 0.093972601 | J15: =D15/D3 -> 0.09418082 | K15: =E15/E3 -> 0.068390938 | L15: =F15/F3 -> 0.078461937 | M15: =AVERAGE(H15:L15) -> 0.086950596 | N15: =MEDIAN(H15:L15) -> 0.093972601 | O15: =N15+5% -> 0.1439726
A16: Other Expenses | B16: 119887106745 | C16: 204876120108 | D16: 205606728132 | E16: 222196927770 | F16: 301371686732 | H16: =B16/B3 -> 0.030005743 | I16: =C16/C3 -> 0.037719262 | J16: =D16/D3 -> 0.035422487 | K16: =E16/E3 -> 0.023922858 | L16: =F16/F3 -> 0.027656418 | M16: =4% -> 0.04
A17: Other Operating Income | B17: 318964577720 | C17: 167385583288 | D17: 355656689271 | E17: 278288788329 | F17: 655571311440 | H17: =B17/B3 -> 0.079831514 | I17: =C17/C3 -> 0.030816968 | J17: =D17/D3 -> 0.061273504 | K17: =E17/E3 -> 0.029961995 | L17: =F17/F3 -> 0.060160774 | M17: =AVERAGE(H17:L17) -> 0.052408951
A18: EBITDA | B18: =B20+B19 -> 706190985525 | C18: =C20+C19 -> 812469030120 | D18: =D20+D19 -> 1765622534130 | E18: =E20+E19 -> 2058580896264 | F18: =F20+F19 -> 2436684521810
A19: Depreciation and amortisation | B19: 534408144380 | C19: 782954247460 | D19: 856743293328 | E19: 883531324989 | F19: 859603231390
A20: EBIT | B20: =B11-B15-B16+B17 -> 171782841145 | C20: =C11-C15-C16+C17 -> 29514782660 | D20: =D11-D15-D16+D17 -> 908879240802 | E20: =E11-E15-E16+E17 -> 1175049571275 | F20: =F11-F15-F16+F17 -> 1577081290420
A21: Interest expense | B21: 109283560320 | C21: 168031934532 | D21: 250499968602 | E21: 237839369526 | F21: 190796075404 | I21: =(C21-B21)/B21 -> 0.53757742 | J21: =(D21-C21)/C21 -> 0.49078786 | K21: =(E21-D21)/D21 -> -0.05054132 | L21: =(F21-E21)/E21 -> -0.19779439 | M21: =AVERAGE(I21:L21) -> 0.19500739
A22: EBT | B22: =B20-B21 -> 62499280825 | C22: =C20-C21 -> -138517151872 | D22: =D20-D21 -> 658379272200 | E22: =E20-E21 -> 937210201749 | F22: =F20-F21 -> 1386285215016
A23: Current corporate income tax expense | B23: 43888070775 | C23: 38111703432 | D23: 135002100324 | E23: 269824313937 | F23: 345502862294
A24: Deferred corporate tax income | B24: -18158757360 | C24: -21772416952 | D24: -22565008908 | E24: -30584822613 | F24: -10790639210
A25: Net profit after tax | B25: =B22-B23-B24 -> 36769967410 | C25: =C22-C23-C24 -> -154856438352 | D25: =D22-D23-D24 -> 545942180784 | E25: =E22-E23-E24 -> 697970710425 | F25: =F22-F23-F24 -> 1051572991932
A26: Attributable to: - The Company's shareholders | B26: 19553861685 | C26: -102948793684 | D26: 584832279876 | E26: 687851813973 | F26: 1038634292340
A27: Attributable to: - Non-controlling interests and Interests of partners in BCC | B27: 17216105725 | C27: -51907644668 | D27: -38890099092 | E27: 10118896452 | F27: 12938699592
A28: Basic earning per share | B28: -28 | C28: -250 | D28: 810 | E28: 1000 | F28: 1541
A31: BALANCE SHEET
A32: ASSETS | B32: 2021 | C32: 2022 | D32: 2023 | E32: 2024 | F32: 2025
A33: CURRENT ASSETS | B33: =SUM(B34:B38) -> 5428797240960 | C33: =SUM(C34:C38) -> 5645895372740 | D33: =SUM(D34:D38) -> 6927879980560 | E33: =SUM(E34:E38) -> 7782381355167 | F33: =SUM(F34:F38) -> 9657061718516
A34: Cash and cash equivalents | B34: 1130703090240 | C34: 2078586541400 | D34: 2256047157280 | E34: 2203268274194 | F34: 1821273980243 | H34: =B34/B3 -> 0.28299613 | I34: =C34/C3 -> 0.3826837 | J34: =D34/D3 -> 0.38867795 | K34: =E34/E3 -> 0.23721514 | L34: =F34/F3 -> 0.16713552 | M34: =AVERAGE(H34:L34) -> 0.29174169 | N34: 0.15
A35: Short-term financial investments | B35: 1544250741200 | C35: 424471711880 | D35: 1278224697680 | E35: 770247363138 | F35: 688956087159 | H35: =B35/B3 -> 0.38650021 | I35: =C35/C3 -> 0.078148492 | J35: =D35/D3 -> 0.22021603 | K35: =E35/E3 -> 0.082928773 | L35: =F35/F3 -> 0.063224444 | M35: =AVERAGE(H35:L35) -> 0.16620359 | N35: 0.15
A36: Short-term receivables | B36: 1935799443760 | C36: 2163333176040 | D36: 2313956884400 | E36: 3469317637527 | F36: 5320195613823
A37: Inventories | B37: 757836145920 | C37: 908560921640 | D37: 999895512000 | E37: 1215947183667 | F37: 1536520885112
A38: Other short-term assets | B38: 60207819840 | C38: 70943021780 | D38: 79755729200 | E38: 123600896641 | F38: 290115152179 | H38: =B38/B3 -> 0.015069013 | I38: =C38/C3 -> 0.013061154 | J38: =D38/D3 -> 0.013740534 | K38: =E38/E3 -> 0.013307505 | L38: =F38/F3 -> 0.026623423 | M38: =AVERAGE(H38:L38) -> 0.016360326 | N38: 0.03
A39: NON-CURRENT ASSETS | B39: =SUM(B40:B41)+SUM(B48:B50) -> 15332405243200 | C39: =SUM(C40:C41)+SUM(C48:C50) -> 15058151318730 | D39: =SUM(D40:D41)+SUM(D48:D50) -> 14704968227040 | E39: =SUM(E40:E41)+SUM(E48:E50) -> 15832176406056 | F39: =SUM(F40:F41)+SUM(F48:F50) -> 18652800964234
A40: Long-term receivables | B40: 50362046080 | C40: 18645737260 | D40: 103902984640 | E40: 319500195972 | F40: 227517444064 | H40: =B40/B3 -> 0.01260478 | I40: =C40/C3 -> 0.003432823 | J40: =D40/D3 -> 0.017900689 | K40: =E40/E3 -> 0.034399026 | L40: =F40/F3 -> 0.020878927 | M40: =AVERAGE(K40:L40) -> 0.027638977
A41: Fixed assets | B41: 12961890042800 | C41: 13567184243890 | D41: 13115351781280 | E41: 12850927344986 | F41: 14607847812254 | H41: =B41/B3 -> 3.2441449 | I41: =C41/C3 -> 2.4978225 | J41: =D41/D3 -> 2.2595485 | K41: =E41/E3 -> 1.3835966 | L41: =F41/F3 -> 1.3405398 | M41: =AVERAGE(I41:L41) -> 1.8703769 | N41: 1.5
A42: Tangible fixed assets | B42: 12784902046560 | C42: 13396281716020 | D42: 12950566249040 | E42: 12689952977516 | F42: 14452833424755
...

Sheet Forecasting
A1: ITEMS | B1: 2025 | C1: 2026 | D1: 2027 | E1: 2028 | F1: 2029 | G1: 2030
A2: Net revenue | B2: 10896989276040 | C2: =Sales!J31 -> 1.2339248e+13 | D2: =Sales!K31 -> 1.4863539e+13 | E2: =Sales!L31 -> 1.62994e+13 | F2: =Sales!M31 -> 1.7615176e+13 | G2: =Sales!N31 -> 1.8137279e+13
A3: Growth rate | C3: =(C2-B2)/B2 -> 0.13235388 | D3: =(D2-C2)/C2 -> 0.20457411 | E3: =(E2-D2)/D2 -> 0.096602928 | F3: =(F2-E2)/E2 -> 0.080725414 | G3: =(G2-F2)/F2 -> 0.02963939
A4: Cost of sales | B4: 8819108718862 | C4: =Sales!J32 -> 9.4068171e+12 | D4: =Sales!K32 -> 1.1315329e+13 | E4: =Sales!L32 -> 1.148927e+13 | F4: =Sales!M32 -> 1.221174e+13 | G4: =Sales!N32 -> 1.2387608e+13 | J4: 2026 | K4: 2027 | L4: 2028 | M4: 2029 | N4: 2030
A5: Gross profit | B5: 2077880557178 | C5: =Sales!J33 -> 2.932431e+12 | D5: =Sales!K33 -> 3.5482097e+12 | E5: =Sales!L33 -> 4.8101303e+12 | F5: =Sales!M33 -> 5.4034363e+12 | G5: =Sales!N33 -> 5.7496706e+12 | I5: EBIT | J5: =C9 -> 1.9479926e+12 | K5: =D9 -> 2.2389592e+12 | L5: =E9 -> 2.5071848e+12 | M5: =F9 -> 2.872338e+12 | N5: =G9 -> 3.1367119e+12
A6: SG&A | B6: 854998891466 | C6: =C2*'Historical Data'!$N$15 -> 1.1595512e+12 | D6: =D2*'Historical Data'!$N$15 -> 1.3967654e+12 | E6: =E2*'Historical Data'!$O$15 -> 2.346667e+12 | F6: =F2*'Historical Data'!$O$15 -> 2.5361027e+12 | G6: =G2*'Historical Data'!$O$15 -> 2.6112712e+12 | I6: Depreciation and amortisation | J6: =Depreciation!G4 -> 8.5390214e+11 | K6: =Depreciation!H4 -> 9.0695639e+11 | L6: =Depreciation!I4 -> 9.4462365e+11 | M6: =Depreciation!J4 -> 9.8514692e+11 | N6: =Depreciation!K4 -> 1.0286885e+12
A7: Other Expenses | B7: 301371686732 | C7: =C2*'Historical Data'!$M$16 -> 4.9356993e+11 | D7: =D2*'Historical Data'!$M$16 -> 5.9454155e+11 | E7: =E2*'Historical Data'!$M$16 -> 6.5197601e+11 | F7: =F2*'Historical Data'!$M$16 -> 7.0460704e+11 | G7: =G2*'Historical Data'!$M$16 -> 7.2549116e+11 | I7: EBITDA | J7: =SUM(J5:J6) -> 2.8018948e+12 | K7: =SUM(K5:K6) -> 3.1459155e+12 | L7: =SUM(L5:L6) -> 3.4518084e+12 | M7: =SUM(M5:M6) -> 3.857485e+12 | N7: =SUM(N5:N6) -> 4.1654003e+12
A8: Other Operating Income | B8: 655571311440 | C8: =B8*(1+2%) -> 6.6868274e+11 | D8: =C8*(1+2%) -> 6.8205639e+11 | E8: =D8*(1+2%) -> 6.9569752e+11 | F8: =E8*(1+2%) -> 7.0961147e+11 | G8: =F8*(1+2%) -> 7.238037e+11
A9: EBIT | B9: 1577081290420 | C9: =C5-C6-C7+C8 -> 1.9479926e+12 | D9: =D5-D6-D7+D8 -> 2.2389592e+12 | E9: =E5-E6-E7+E8 -> 2.5071848e+12 | F9: =F5-F6-F7+F8 -> 2.872338e+12 | G9: =G5-G6-G7+G8 -> 3.1367119e+12
A10: Interest expense | B10: 190796075404 | C10: =Debt!G10 -> 2.990035e+11 | D10: =Debt!H10 -> 3.0418996e+11 | E10: =Debt!I10 -> 3.5065908e+11 | F10: =Debt!J10 -> 2.1865523e+11 | G10: =Debt!K10 -> 2.056972e+11
A11: EBT | B11: 1386285215016 | C11: =C9-C10 -> 1.6489891e+12 | D11: =D9-D10 -> 1.9347692e+12 | E11: =E9-E10 -> 2.1565257e+12 | F11: =F9-F10 -> 2.6536828e+12 | G11: =G9-G10 -> 2.9310147e+12
A12: Tax (20%) | B12: 334712223084 | C12: =WACC!$B$13*C11 -> 3.2979782e+11 | D12: =WACC!$B$13*D11 -> 3.8695384e+11 | E12: =WACC!$B$13*E11 -> 4.3130513e+11 | F12: =WACC!$B$13*F11 -> 5.3073656e+11 | G12: =WACC!$B$13*G11 -> 5.8620294e+11
A13: Net profit after tax | B13: 1051572991932 | C13: =C11-C12 -> 1.3191913e+12 | D13: =D11-D12 -> 1.5478154e+12 | E13: =E11-E12 -> 1.7252205e+12 | F13: =F11-F12 -> 2.1229462e+12 | G13: =G11-G12 -> 2.3448117e+12
A14: Attributable to: - The Company's shareholders | B14: 1038634292340 | C14: =C13-C15 -> 1.3058644e+12 | D14: =D13-D15 -> 1.5340887e+12 | E14: =E13-E15 -> 1.7110821e+12 | F14: =F13-F15 -> 2.1083836e+12 | G14: =G13-G15 -> 2.3298122e+12
A15: Attributable to: - Non-controlling interests and Interests of partners in BCC | B15: 12938699592 | C15: =B15*(1+3%) -> 1.3326861e+10 | D15: =C15*(1+3%) -> 1.3726666e+10 | E15: =D15*(1+3%) -> 1.4138466e+10 | F15: =E15*(1+3%) -> 1.456262e+10 | G15: =F15*(1+3%) -> 1.4999499e+10
A16: Additional to retain earning | C16: =C17*C14 -> 1.2405712e+12 | D16: =D17*D14 -> 1.5340887e+12 | E16: =E17*E14 -> 1.7110821e+12 | F16: =F17*F14 -> 1.8975453e+12 | G16: =G17*G14 -> 2.096831e+12
A17: Retention Ratio | C17: 0.95 | D17: 1 | E17: 1 | F17: 0.9 | G17: 0.9
A20: BALANCE SHEET
A21: ASSETS | B21: 2025 | C21: 2026 | D21: 2027 | E21: 2028 | F21: 2029 | G21: 2030
A22: CURRENT ASSETS | B22: 9657061718516 | C22: =SUM(C23:C27) -> 1.0315218e+13 | D22: =SUM(D23:D27) -> 1.2233935e+13 | E22: =SUM(E23:E27) -> 1.3132849e+13 | F22: =SUM(F23:F27) -> 1.4523141e+13 | G22: =SUM(G23:G27) -> 1.6157936e+13
A23: Cash and cash equivalents | B23: 1821273980243 | C23: ='Historical Data'!$N$34*C2-C59 -> 1.8508872e+12 | D23: ='Historical Data'!$N$34*D2 -> 2.2295308e+12 | E23: ='Historical Data'!$N$34*E2 -> 2.44491e+12 | F23: ='Historical Data'!$N$34*F2-F59 -> 2.6422764e+12 | G23: ='Historical Data'!$N$34*G2-G59 -> 3.018642e+12
A24: Short-term financial investments | B24: 688956087159 | C24: 688956087159 | D24: 688956087159 | E24: 688956087159 | F24: =792299500232.85-F60 -> 1.1299615e+12 | G24: =911144425267.777-G60 -> 2.1033449e+12
A25: Short-term receivables | B25: 5320195613823 | C25: =C2*CCC!$H$2/365 -> 5.4089855e+12 | D25: =D2*CCC!$H$2/365 -> 6.5155239e+12 | E25: =E2*CCC!$H$2/365 -> 7.1449425e+12 | F25: =F2*CCC!$H$2/365 -> 7.721721e+12 | G25: =G2*CCC!$H$2/365 -> 7.9505881e+12
A26: Inventories | B26: 1536520885112 | C26: =C4*CCC!$H$3/365 -> 2.0617681e+12 | D26: =D4*CCC!$H$3/365 -> 2.4800721e+12 | E26: =E4*CCC!$H$3/365 -> 2.5181961e+12 | F26: =F4*CCC!$H$3/365 -> 2.6765457e+12 | G26: =G4*CCC!$H$3/365 -> 2.7150923e+12
A27: Other short-term assets | B27: 290115152179 | C27: =B27*(1+5%) -> 3.0462091e+11 | D27: =C27*(1+5%) -> 3.1985196e+11 | E27: =D27*(1+5%) -> 3.3584455e+11 | F27: =E27*(1+5%) -> 3.5263678e+11 | G27: =F27*(1+5%) -> 3.7026862e+11
A28: NON-CURRENT ASSETS | B28: 18652800964234 | C28: =SUM(C29:C33) -> 2.0363168e+13 | D28: =SUM(D29:D33) -> 2.1664785e+13 | E28: =SUM(E29:E33) -> 2.0231358e+13 | F28: =SUM(F29:F33) -> 2.1137908e+13 | G28: =SUM(G29:G33) -> 2.2153676e+13
A29: Long-term receivables | B29: 227517444064 | C29: =C2*'Historical Data'!$M$40 -> 3.4104419e+11 | D29: =D2*'Historical Data'!$M$40 -> 4.10813e+11 | E29: =E2*'Historical Data'!$M$40 -> 4.5049874e+11 | F29: =F2*'Historical Data'!$M$40 -> 4.8686544e+11 | G29: =G2*'Historical Data'!$M$40 -> 5.0129583e+11
A30: Fixed assets | B30: 14607847812254 | C30: ='Fixed Asset'!H4 -> 1.5931564e+13 | D30: ='Fixed Asset'!I4 -> 1.7078704e+13 | E30: ='Fixed Asset'!J4 -> 1.7672723e+13 | F30: ='Fixed Asset'!K4 -> 1.8329358e+13 | G30: ='Fixed Asset'!L4 -> 1.9052398e+13
A31: Long-term assets in progress | B31: 2203939665047 | C31: =(B31-2043730452301)+'Drilling Service'!H67 -> 2396389212746 | D31: =C31-'Drilling Service'!H67+'Drilling Service'!H68 -> 2396389212746 | E31: =(D31-'Drilling Service'!H68)*(1+50%) -> 240313819119 | F31: =E31*(1+50%) -> 3.6047073e+11 | G31: =F31*(1+50%) -> 5.4070609e+11
A32: Long-term financial investments | B32: 770410778053 | C32: =B32*(1+5%) -> 8.0893132e+11 | D32: =C32*(1+5%) -> 8.4937788e+11 | E32: =D32*(1+5%) -> 8.9184678e+11 | F32: =E32*(1+5%) -> 9.3643912e+11 | G32: =F32*(1+5%) -> 9.8326107e+11
A33: Other long-term assets | B33: 843085264816 | C33: =B33*(1+5%) -> 8.8523953e+11 | D33: =C33*(1+5%) -> 9.295015e+11 | E33: =D33*(1+5%) -> 9.7597658e+11 | F33: =E33*(1+5%) -> 1.0247754e+12 | G33: =F33*(1+5%) -> 1.0760142e+12
A34: TOTAL ASSETS | B34: 28309862682750 | C34: =SUM(C22,C28) -> 3.0678386e+13 | D34: =SUM(D22,D28) -> 3.389872e+13 | E34: =SUM(E22,E28) -> 3.3364208e+13 | F34: =SUM(F22,F28) -> 3.566105e+13 | G34: =SUM(G22,G28) -> 3.8311612e+13
A35: LIABILITIES | B35: 11211575733628 | C35: =SUM(C36,C41) -> 1.0811906e+13 | D35: =SUM(D36,D41) -> 1.0625284e+13 | E35: =SUM(E36,E41) -> 8.0371417e+12 | F35: =SUM(F36,F41) -> 8.0836136e+12 | G35: =SUM(G36,G41) -> 8.2739348e+12
A36: Current liabilities | B36: 6619272245050 | C36: =SUM(C37:C40) -> 6.8158423e+12 | D36: =SUM(D37:D40) -> 6.8820024e+12 | E36: =SUM(E37:E40) -> 6.7021826e+12 | F36: =SUM(F37:F40) -> 6.9535132e+12 | G36: =SUM(G37:G40) -> 7.1099313e+12
A37: Account payable | B37: 2592727186371 | C37: =C4*CCC!$H$4/365 -> 2.5772102e+12 | D37: =D4*CCC!$H$4/365 -> 3.1000902e+12 | E37: =E4*CCC!$H$4/365 -> 3.1477452e+12 | F37: =F4*CCC!$H$4/365 -> 3.3456821e+12 | G37: =G4*CCC!$H$4/365 -> 3.3938653e+12
A38: Other short-term payable | B38: 2774442492172 | C38: =B38*(1+3%) -> 2.8576758e+12 | D38: =C38*(1+3%) -> 2.943406e+12 | E38: =D38*(1+3%) -> 3.0317082e+12 | F38: =E38*(1+3%) -> 3.1226595e+12 | G38: =F38*(1+3%) -> 3.2163393e+12
A39: Short-term loans | B39: 821033901691 | C39: 9.3695567e+11 | D39: =965064340977.758+D58 -> 3.8118541e+11 | E39: =820304689831.094+E58 -> 5.1688789e+10 | F39: =697258986356.43+F58 -> 0 | G39: =592670138402.966+G58 -> 0
A40: Short-term provisions | B40: 431068664816 | C40: =B40*(1+3%) -> 4.4400072e+11 | D40: =C40*(1+3%) -> 4.5732075e+11 | E40: =D40*(1+3%) -> 4.7104037e+11 | F40: =E40*(1+3%) -> 4.8517158e+11 | G40: =F40*(1+3%) -> 4.9972673e+11
A41: Long-term liabilities | B41: 4592303488578 | C41: =SUM(C42:C44) -> 3.9960635e+12 | D41: =SUM(D42:D44) -> 3.743282e+12 | E41: =SUM(E42:E44) -> 1.3349591e+12 | F41: =SUM(F42:F44) -> 1.1301004e+12 | G41: =SUM(G42:G44) -> 1.1640035e+12
A42: Long-term loans | B42: 3588223884700 | C42: =3742889839254.15+C57 -> 2.9618615e+12 | D42: =4429690725514.91+D57 -> 2.6780539e+12 | E42: =2543621919291.48+E57 -> 2.3777422e+11 | F42: =2467313261712.74+F57 -> 0 | G42: =2393293863861.35+G57 -> 0
...

Sheet Debt
B2: 2021 | C2: 2022 | D2: 2023 | E2: 2024 | F2: 2025 | G2: 2026 | H2: 2027 | I2: 2028 | J2: 2029 | K2: 2030
A3: Interest expense | B3: 109283560320 | C3: 168031934532 | D3: 250499968602 | E3: 237839369526 | F3: =Forecasting!B10 -> 190796075404 | G3: =B8*F6 -> 2.8660176e+11 | H3: =$B$8*G6 -> 2.5342312e+11 | I3: =$B$8*H6 -> 1.9885056e+11 | J3: =$B$8*I6 -> 1.8815095e+10 | K3: =$B$8*J6 -> 0
A4: Short-term loans | B4: 748408238640 | C4: 835317024600 | D4: 553352813440 | E4: 507298751244 | F4: =Forecasting!B39 -> 821033901691 | G4: =Forecasting!C39 -> 9.3695567e+11 | H4: =Forecasting!D39 -> 3.8118541e+11 | I4: =Forecasting!E39 -> 5.1688789e+10 | J4: =Forecasting!F39 -> 0 | K4: =Forecasting!G39 -> 0
A5: Long-term loans | B5: 3205703464640 | C5: 2999752062520 | D5: 2787681809360 | E5: 2541390152379 | F5: =Forecasting!B42 -> 3588223884700 | G5: =Forecasting!C42 -> 2.9618615e+12 | H5: =Forecasting!D42 -> 2.6780539e+12 | I5: =Forecasting!E42 -> 2.3777422e+11 | J5: =Forecasting!F42 -> 0 | K5: =Forecasting!G42 -> 0
A6: Total | B6: =SUM(B4:B5) -> 3954111703280 | C6: =SUM(C4:C5) -> 3835069087120 | D6: =SUM(D4:D5) -> 3341034622800 | E6: =SUM(E4:E5) -> 3048688903623 | F6: =SUM(F4:F5) -> 4409257786391 | G6: =SUM(G4:G5) -> 3.8988172e+12 | H6: =SUM(H4:H5) -> 3.0592393e+12 | I6: =SUM(I4:I5) -> 2.89463e+11 | ... K6: =SUM(K4:K5) -> 0
A7: Interest rate | B7: =B3/B6 -> 0.027637955 | C7: =C3/C6 -> 0.043814578 | D7: =D3/D6 -> 0.074976765 | E7: =E3/E6 -> 0.078013657 | F7: =F3/F6 -> 0.043271699
A8: Interest rate | B8: 0.065
G10: 2.990035e+11 | H10: 3.0418996e+11 | I10: 3.5065908e+11 | J10: 2.1865523e+11 | K10: 2.056972e+11

Sheet Fixed Asset
C3: 2021 | D3: 2022 | E3: 2023 | F3: 2024 | G3: 2025 | H3: 2026 | I3: 2027 | J3: 2028 | K3: 2029 | L3: 2030
B4: Fixed assets | C4: =C5+C8 -> 12961890042800 | D4: =D5+D8 -> 13567184243890 | E4: =E5+E8 -> 13115351781280 | F4: =F5+F8 -> 12850927344986 | G4: =G5+G8 -> 14607847812254 | H4: =H5+H8 -> 1.5931564e+13 | I4: =I5+I8 -> 1.7078704e+13 | J4: =J5+J8 -> 1.7672723e+13 | ... L4: =L5+L8 -> 1.9052398e+13
B5: Tangible fixed assets | C5: 12784902046560 | D5: 13396281716020 | E5: 12950566249040 | F5: 12689952977516 | G5: 14452833424755 | H5: =H6+H7 -> 1.5768799e+13 | I5: =I6+I7 -> 1.69078e+13 | J5: =J6+J7 -> 1.7493274e+13 | K5: =K6+K7 -> 1.8140937e+13 | L5: =L6+L7 -> 1.8854556e+13
B6: Cost | C6: 23187118919200 | D6: 24822036561060 | E6: 25490804674720 | F6: 26578381033464 | G6: 29180690127632 | H6: =G6+'Drilling Service'!H67 -> 31416870127632 | I6: =H6+'Drilling Service'!H68 -> 33653050127632 | J6: =I6*(1+5%) -> 3.5335703e+13 | K6: =J6*(1+5%) -> 3.7102488e+13 | L6: =K6*(1+5%) -> 38957612154000
B7: Accumulated depreciation | C7: -10402216872640 | D7: -11425754845040 | E7: -12540238425680 | F7: -13878428055948 | G7: -14727856747877 | H7: =G7-H12 -> -1.5648071e+13 | I7: =H7-I12 -> -1.674525e+13 | J7: =I7-J12 -> -1.7842429e+13 | K7: =J7-K12 -> -1.8961551e+13 | L7: =K7-L12 -> -2.0103056e+13
B8: Intangible assets | C8: 176987996240 | D8: 170902527870 | E8: 164785532240 | F8: 160974367470 | G8: 155014387499 | H8: =G8*(1+5%) -> 1.6276511e+11 | I8: =H8*(1+5%) -> 1.7090336e+11 | J8: =I8*(1+5%) -> 1.7944853e+11 | K8: =J8*(1+5%) -> 1.8842096e+11 | L8: =K8*(1+5%) -> 1.97842e+11
B10: Change in tangible fixed asset | D10: =D6-C6 -> 1634917641860 | E10: =E6-D6 -> 668768113660 | F10: =F6-E6 -> 1087576358744 | G10: =G6-F6 -> 2602309094168 | H10: =H6-G6 -> 2236180000000 | I10: =I6-H6 -> 2236180000000 | J10: =J6-I6 -> 1.6826525e+12 | K10: =K6-J6 -> 1.7667851e+12 | L10: =L6-K6 -> 1.8551244e+12
B12: Depreciation expense | D12: =ABS(D7)-ABS(C7) -> 1023537972400 | E12: =ABS(E7)-ABS(D7) -> 1114483580640 | F12: =ABS(F7)-ABS(E7) -> 1338189630268 | G12: =ABS(G7)-ABS(F7) -> 849428691929 | H12: =G12/6*6.5 -> 9.2021442e+11 | I12: =H12/6.5*7.75 -> 1.0971787e+12 | J12: =I12/7.75*7.75 -> 1.0971787e+12 | K12: =J12*(1+2%) -> 1.1191223e+12 | L12: =K12*(1+2%) -> 1.1415047e+12

Sheet Depreciation
U2: 15
B3: 2021 | C3: 2022 | D3: 2023 | E3: 2024 | F3: 2025 | G3: 2026 | H3: 2027 | I3: 2028 | J3: 2029 | K3: 2030
A4: Depreciation and Armotization | B4: 534408144380 | C4: 782954247460 | D4: 856743293328 | E4: 883531324989 | F4: 859603231390 | G4: =AVERAGE(G6,G10) -> 8.5390214e+11 | H4: =AVERAGE(H6,H10) -> 9.0695639e+11 | I4: =AVERAGE(I6,I10) -> 9.4462365e+11 | J4: =AVERAGE(J6,J10) -> 9.8514692e+11 | K4: =AVERAGE(K6,K10) -> 1.0286885e+12
A5: Tangible | B5: 12784902046560 | C5: 13396281716020 | D5: 12950566249040 | E5: 12689952977516 | F5: 14452833424755 | G5: ='Fixed Asset'!H5 -> 1.5768799e+13 | H5: ='Fixed Asset'!I5 -> 1.69078e+13 | I5: ='Fixed Asset'!J5 -> 1.7493274e+13 | J5: ='Fixed Asset'!K5 -> 1.8140937e+13 | K5: ='Fixed Asset'!L5 -> 1.8854556e+13
A6: Ratio | B6: =B4/B5 -> 0.04179994 | C6: =C4/C5 -> 0.058445639 | D6: =D4/D5 -> 0.066154891 | E6: =E4/E5 -> 0.069624476 | F6: =F4/F5 -> 0.05947645 | G6: =$B$14*G5 -> 9.3194042e+11 | H6: =$B$14*H5 -> 9.9925572e+11 | I6: =$B$14*I5 -> 1.0338574e+12 | J6: =$B$14*J5 -> 1.0721344e+12 | K6: =$B$14*K5 -> 1.1143096e+12
A7: DA Tangible
A8: Intangible | B8: 176987996240 | C8: 170902527870 | D8: 164785532240 | E8: 160974367470 | F8: 155014387499 | G8: ='Fixed Asset'!H8 -> 1.6276511e+11 | H8: ='Fixed Asset'!I8 -> 1.7090336e+11 | I8: ='Fixed Asset'!J8 -> 1.7944853e+11 | J8: ='Fixed Asset'!K8 -> 1.8842096e+11 | K8: ='Fixed Asset'!L8 -> 1.97842e+11
A9: Ratio | B9: =B4/B8 -> 3.0194598 | C9: =C4/C8 -> 4.5812912 | D9: =D4/D8 -> 5.1991415 | E9: =E4/E8 -> 5.488646 | F9: =F4/F8 -> 5.5453126
A10: DA Intangible | G10: =$B$15*G8 -> 7.7586386e+11 | H10: =$B$15*H8 -> 8.1465706e+11 | I10: =$B$15*I8 -> 8.5538991e+11 | J10: =$B$15*J8 -> 8.9815941e+11 | K10: =$B$15*K8 -> 9.4306738e+11
A13: Average
A14: Tangible | B14: =AVERAGE(B6:F6) -> 0.059100279
A15: Intangbile | B15: =AVERAGE(B9:F9) -> 4.7667702

Sheet CCC
B1: 2021 | C1: 2022 | D1: 2023 | E1: 2024 | F1: 2025 | G1: Average | H1: Target
A2: DSO | B2: ='Historical Data'!B36/'Historical Data'!B3*365 -> 176.84189 | C2: ='Historical Data'!C36/'Historical Data'!C3*365 -> 145.37446 | D2: ='Historical Data'!D36/'Historical Data'!D3*365 -> 145.509 | E2: ='Historical Data'!E36/'Historical Data'!E3*365 -> 136.33644 | F2: ='Historical Data'!F36/'Historical Data'!F3*365 -> 178.20256 | G2: =AVERAGE(B2:F2) -> 156.45287 | H2: 160
A3: DIO | B3: ='Historical Data'!B37/'Historical Data'!B7*365 -> 76.32244 | C3: ='Historical Data'!C37/'Historical Data'!C7*365 -> 68.317393 | D3: ='Historical Data'!D37/'Historical Data'!D7*365 -> 81.122125 | E3: ='Historical Data'!E37/'Historical Data'!E7*365 -> 58.909961 | F3: ='Historical Data'!F37/'Historical Data'!F7*365 -> 63.592608 | G3: =AVERAGE(B3:F3) -> 69.652905 | H3: 80
A4: DPO | B4: ='Historical Data'!B54/'Historical Data'!B7*365 -> 78.53542 | C4: ='Historical Data'!C54/'Historical Data'!C7*365 -> 42.69572 | D4: ='Historical Data'!D54/'Historical Data'!D7*365 -> 46.197321 | E4: ='Historical Data'!E54/'Historical Data'!E7*365 -> 56.811789 | F4: ='Historical Data'!F54/'Historical Data'!F7*365 -> 107.30624 | G4: =AVERAGE(B4:F4) -> 66.309299 | H4: 100
A5: CCC | B5: =B2+B3-B4 -> 174.62891 | C5: =C2+C3-C4 -> 170.99614 | D5: =D2+D3-D4 -> 180.43381 | E5: =E2+E3-E4 -> 138.43461 | F5: =F2+F3-F4 -> 134.48893 | G5: =G2+G3-G4 -> 159.79648 | H5: =H2+H3-H4 -> 140

Sheet Sales
I1: Forecast
A2: Drilling services | B2: 2021 | C2: 2022 | D2: 2023 | E2: 2024 | F2: 2025 | J2: 2026 | K2: 2027 | L2: 2028 | M2: 2029 | N2: 2030
A3: Revenue | B3: 1837734722430 | C3: 3535403580588 | D3: 4067897158962 | E3: 5635320312015 | F3: 6052017310330 | J3: ='Drilling Service'!C81 -> 7274556620000 | K3: ='Drilling Service'!D81 -> 8714426345000 | L3: ='Drilling Service'!E81 -> 9869117350000 | M3: ='Drilling Service'!F81 -> 10678371161000 | N3: ='Drilling Service'!G81 -> 10986128722000
A4: % on net revenue | B4: =B3/'Historical Data'!B3 -> 0.45995435 | C4: =C3/'Historical Data'!C3 -> 0.65089487 | D4: =D3/'Historical Data'!D3 -> 0.70082841 | E4: =E3/'Historical Data'!E3 -> 0.60672743 | F4: =F3/'Historical Data'!F3 -> 0.55538435
A5: % growth | C5: =(C3-B3)/B3 -> 0.92378342 | D5: =(D3-C3)/C3 -> 0.15061748 | E5: =(E3-D3)/D3 -> 0.38531533 | F5: =(F3-E3)/E3 -> 0.0739438 | J5: =(J3-F3)/F3 -> 0.20200526 | K5: =(K3-J3)/J3 -> 0.1979323 | L5: =(L3-K3)/K3 -> 0.13250339 | M5: =(M3-L3)/L3 -> 0.081998601 | N5: =(N3-M3)/M3 -> 0.028820647
A6: COGS | B6: 1835180033970 | C6: 3408806370904 | D6: 3204407818170 | E6: 4425686255586 | F6: 4847519368672 | J6: =F6/6*6.5 -> 5.2514793e+12 | K6: =J6/6.5*7.75 -> 6.2613792e+12 | L6: =K6/7.75*7.75 -> 6.2613792e+12 | M6: =L6*(1+5%) -> 6.5744481e+12 | N6: =M6 -> 6.5744481e+12
A7: % on revenue | B7: =B6/B3 -> 0.99860987 | C7: =C6/C3 -> 0.96419158 | D7: =D6/D3 -> 0.78773078 | E7: =E6/E3 -> 0.78534777 | F7: =F6/F3 -> 0.80097579 | G7: =75% -> 0.75
A8: Gross profit | B8: 2554688460 | C8: 126597209684 | D8: 863489340792 | E8: 1209634056429 | F8: 1204497941658 | J8: =J3-J6 -> 2.0230773e+12 | K8: =K3-K6 -> 2.4530472e+12 | L8: =L3-L6 -> 3.6077382e+12 | M8: =M3-M6 -> 4.103923e+12 | N8: =N3-N6 -> 4.4116806e+12
A9: GPM
A11: Trading | B11: 2021 | C11: 2022 | D11: 2023 | E11: 2024 | F11: 2025 | J11: 2026 | K11: 2027 | L11: 2028 | M11: 2029 | N11: 2030
A12: Revenue | B12: 495288090110 | C12: 114863242736 | D12: 157142368266 | E12: 1207086301149 | F12: 617651216604 | J12: =F12*(1+30%) -> 8.0294658e+11 | K12: =J12*(1+30%) -> 1.0438306e+12 | L12: =F12*(1+5%) -> 6.4853378e+11 | M12: =L12*(1+5%) -> 6.8096047e+11 | N12: =M12*(1+5%) -> 7.1500849e+11
A13: % on net revenue | B13: =B12/'Historical Data'!B3 -> 0.12396235 | C13: =C12/'Historical Data'!C3 -> 0.021147203 | D13: =D12/'Historical Data'!D3 -> 0.027072915 | E13: =E12/'Historical Data'!E3 -> 0.12996109 | F13: =F12/'Historical Data'!F3 -> 0.056680905 | G13: =AVERAGE(B13:F13) -> 0.071764892
A14: % growth | C14: =(C12-B12)/B12 -> -0.76808802 | D14: =(D12-C12)/C12 -> 0.36808229 | E14: =(E12-D12)/D12 -> 6.6814822 | F14: =(F12-E12)/E12 -> -0.4883123
A15: COGS | B15: 463541343165 | C15: 86903506360 | D15: 144759187677 | E15: 1163229831462 | F15: 573801413642 | J15: =J12*$G$16 -> 7.4594184e+11 | K15: =K12*$G$16 -> 9.6972439e+11 | L15: =L12*$G$16 -> 6.0249148e+11 | M15: =M12*$G$16 -> 6.3261606e+11 | N15: =N12*$G$16 -> 6.6424686e+11
A16: % on revenue | B16: =B15/B12 -> 0.93590246 | C16: =C15/C12 -> 0.75658239 | D16: =D15/D12 -> 0.9211977 | E16: =E15/E12 -> 0.96366749 | F16: =F15/F12 -> 0.92900556 | G16: =MEDIAN(B16:F16) -> 0.92900556
A17: Gross profit | B17: 31746746945 | C17: 27959736376 | D17: 12383180589 | E17: 43856469687 | F17: 43849802962 | J17: =J12-J15 -> 5.7004744e+10 | K17: =K12-K15 -> 7.4106167e+10 | L17: =L12-L15 -> 4.6042293e+10 | M17: =M12-M15 -> 4.8344408e+10 | N17: =N12-N15 -> 5.0761628e+10
A18: GPM
A20: Other service | B20: 2021 | C20: 2022 | D20: 2023 | E20: 2024 | F20: 2025 | J20: 2026 | K20: 2027 | L20: 2028 | M20: 2029 | N20: 2030
A21: Revenue | B21: 1662449152130 | C21: 1781337790496 | D21: 1579372957695 | E21: 2445652694382 | F21: 4227320749106 | J21: =$G$24*J3 -> 4.2617449e+12 | K21: =$G$24*K3 -> 5.1052819e+12 | L21: =$G$24*L3 -> 5.781749e+12 | M21: =$G$24*M3 -> 6.2558444e+12 | N21: =$G$24*N3 -> 6.4361419e+12
A22: % on net revenue | B22: =B21/'Historical Data'!B3 -> 0.4160833 | C22: =C21/'Historical Data'!C3 -> 0.32795793 | D22: =D21/'Historical Data'!D3 -> 0.27209868 | E22: =E21/'Historical Data'!E3 -> 0.26331149 | F22: =F21/'Historical Data'!F3 -> 0.38793474 | G22: 0.3
A23: % growth | C23: =(C21-B21)/B21 -> 0.07151415 | D23: =(D21-C21)/C21 -> -0.11337818 | E23: =(E21-D21)/D21 -> 0.54849599 | F23: =(F21-E21)/E21 -> 0.72850412
A24: & on drilling service | B24: =B21/B3 -> 0.90461868 | C24: =C21/C3 -> 0.50385699 | D24: =D21/D3 -> 0.38825292 | E24: =E21/E3 -> 0.43398646 | F24: =F21/F3 -> 0.6984978 | G24: =AVERAGE(B24:F24) -> 0.58584257
A25: COGS | B25: 1325510141170 | C25: 1358467406164 | D25: 1149751873764 | E25: 1944966424596 | F25: 3397787936548 | J25: =J21*$G$26 -> 3.4093959e+12 | K25: =K21*$G$26 -> 4.0842255e+12 | L25: =L21*$G$26 -> 4.6253992e+12 | M25: =M21*$G$26 -> 5.0046755e+12 | N25: =N21*$G$26 -> 5.1489135e+12
A26: % on revenue | B26: =B25/B21 -> 0.79732372 | C26: =C25/C21 -> 0.76261078 | D26: =D25/D21 -> 0.72797997 | E26: =E25/E21 -> 0.79527499 | F26: =F25/F21 -> 0.80376866 | G26: 0.8
A27: Gross profit | B27: 336939010960 | C27: 422870384332 | D27: 429621083931 | E27: 500686269786 | F27: 829532812558 | J27: =J21-J25 -> 8.5234899e+11 | K27: =K21-K25 -> 1.0210564e+12 | L27: =L21-L25 -> 1.1563498e+12 | M27: =M21-M25 -> 1.2511689e+12 | N27: =N21-N25 -> 1.2872284e+12
A28: GPM
J30: 2026 | K30: 2027 | L30: 2028 | M30: 2029 | N30: 2030
I31: Net Revenue | J31: =SUM(J3,J12,J21) -> 1.2339248e+13 | K31: =SUM(K3,K12,K21) -> 1.4863539e+13 | L31: =SUM(L3,L12,L21) -> 1.62994e+13 | M31: =SUM(M3,M12,M21) -> 1.7615176e+13 | N31: =SUM(N3,N12,N21) -> 1.8137279e+13
I32: COGS | J32: =SUM(J6,J15,J25) -> 9.4068171e+12 | K32: =SUM(K6,K15,K25) -> 1.1315329e+13 | L32: =SUM(L6,L15,L25) -> 1.148927e+13 | M32: =SUM(M6,M15,M25) -> 1.221174e+13 | N32: =SUM(N6,N15,N25) -> 1.2387608e+13
I33: Gross profit | J33: =SUM(J8,J17,J27) -> 2.932431e+12 | K33: =SUM(K8,K17,K27) -> 3.5482097e+12 | L33: =SUM(L8,L17,L27) -> 4.8101303e+12 | M33: =SUM(M8,M17,M27) -> 5.4034363e+12 | N33: =SUM(N8,N17,N27) -> 5.7496706e+12

Sheet Drilling Service
B2: PV DRILLING I | C2: 2026 | D2: 2027 | E2: 2028 | F2: 2029 | G2: 2030
B3: Rig day rate (USD per day) | C3: 90000 | D3: 95000 | E3: 95000 | F3: 95000 | G3: 100000 | I3: Utilization rate
B4: % price increase | I4: 0.98
B5: Day of working | C5: =365*$I$4 -> 357.7 | D5: =365*$I$4 -> 357.7 | E5: =365*$I$4 -> 357.7 | F5: =365*$I$4 -> 357.7 | G5: =365*$I$4 -> 357.7
B6: Day of not working | C6: =365-C5 -> 7.3 | D6: =365-D5 -> 7.3 | E6: =365-E5 -> 7.3 | F6: =365-F5 -> 7.3 | G6: =365-G5 -> 7.3
B7: Revenue | C7: =C3*C5 -> 32193000 | D7: =D3*D5 -> 33981500 | E7: =E3*E5 -> 33981500 | F7: =F3*F5 -> 33981500 | G7: =G3*G5 -> 35770000
B9: PV DRILLING II | C9: 2026 | D9: 2027 | E9: 2028 | F9: 2029 | G9: 2030
B10: Rig day rate (USD per day) | C10: 90000 | D10: 90000 | E10: 90000 | F10: 95000 | G10: 100000
B11: % price increase
B12: Day of working | C12: =C5 -> 357.7 | D12: =D5 -> 357.7 | E12: =E5 -> 357.7 | F12: =F5 -> 357.7 | G12: =G5 -> 357.7
B13: Day of not working | C13: =365-C12 -> 7.3 | D13: =365-D12 -> 7.3 | E13: =365-E12 -> 7.3 | F13: =365-F12 -> 7.3 | G13: =365-G12 -> 7.3
B14: Revenue | C14: =C10*C12 -> 32193000 | D14: =D10*D12 -> 32193000 | E14: =E10*E12 -> 32193000 | F14: =F10*F12 -> 33981500 | G14: =G10*G12 -> 35770000
B16: PV DRILLING III | C16: 2026 | D16: 2027 | E16: 2028 | F16: 2029 | G16: 2030
B17: Rig day rate (USD per day) | C17: 90000 | D17: 90000 | E17: 90000 | F17: 100000 | G17: 100000
B18: % price increase
B19: Day of working | C19: =C5 -> 357.7 | D19: =D5 -> 357.7 | E19: =E5 -> 357.7 | F19: =F5 -> 357.7 | G19: =G5 -> 357.7
B20: Day of not working | C20: =365-C19 -> 7.3 | D20: =365-D19 -> 7.3 | E20: =365-E19 -> 7.3 | F20: =365-F19 -> 7.3 | G20: =365-G19 -> 7.3
B21: Revenue | C21: =C17*C19 -> 32193000 | D21: =D17*D19 -> 32193000 | E21: =E17*E19 -> 32193000 | F21: =F17*F19 -> 35770000 | G21: =G17*G19 -> 35770000
B23: PV DRILLING VI | C23: 2026 | D23: 2027 | E23: 2028 | F23: 2029 | G23: 2030
B24: Rig day rate (USD per day) | C24: 90000 | D24: 95000 | E24: 95000 | F24: 100000 | G24: 100000
B25: % price increase
B26: Day of working | C26: =C5 -> 357.7 | D26: =D5 -> 357.7 | E26: =E5 -> 357.7 | F26: =F5 -> 357.7 | G26: =G5 -> 357.7
B27: Day of not working | C27: =365-C26 -> 7.3 | D27: =365-D26 -> 7.3 | E27: =365-E26 -> 7.3 | F27: =365-F26 -> 7.3 | G27: =365-G26 -> 7.3
B28: Revenue | C28: =C24*C26 -> 32193000 | D28: =D24*D26 -> 33981500 | E28: =E24*E26 -> 33981500 | F28: =F24*F26 -> 35770000 | G28: =G24*G26 -> 35770000
B30: PV DRILLING VIII | C30: 2026 | D30: 2027 | E30: 2028 | F30: 2029 | G30: 2030
B31: Rig day rate (USD per day) | C31: 90000 | D31: 95000 | E31: 95000 | F31: 100000 | G31: 100000
B32: % price increase
B33: Day of working | C33: 339 | D33: =C26 -> 357.7 | E33: =D26 -> 357.7 | F33: =E26 -> 357.7 | G33: =F26 -> 357.7
B34: Day of not working | C34: =365-C33 -> 26 | D34: =365-D33 -> 7.3 | E34: =365-E33 -> 7.3 | F34: =365-F33 -> 7.3 | G34: =365-G33 -> 7.3
B35: Revenue | C35: =C31*C33 -> 30510000 | D35: =D31*D33 -> 33981500 | E35: =E31*E33 -> 33981500 | F35: =F31*F33 -> 35770000 | G35: =G31*G33 -> 35770000
B37: PV DRILLING IX | C37: 2026 | D37: 2027 | E37: 2028 | F37: 2029 | G37: 2030
B38: Rig day rate (USD per day) | C38: 90000 | D38: 95000 | E38: 95000 | F38: 100000 | G38: 100000
B39: % price increase
B40: Day of working | C40: 223 | D40: =D33 -> 357.7 | E40: =E33 -> 357.7 | F40: =F33 -> 357.7 | G40: =G33 -> 357.7
B41: Day of not working | C41: =365-C40 -> 142 | D41: =365-D40 -> 7.3 | E41: =365-E40 -> 7.3 | F41: =365-F40 -> 7.3 | G41: =365-G40 -> 7.3
B42: Revenue | C42: =C38*C40 -> 20070000 | D42: =D38*D40 -> 33981500 | E42: =E38*E40 -> 33981500 | F42: =F38*F40 -> 35770000 | G42: =G38*G40 -> 35770000
B44: PV DRILLING V | C44: 2026 | D44: 2027 | E44: 2028 | F44: 2029 | G44: 2030
B45: Rig day rate (USD per day) | C45: 90000 | D45: 90000 | E45: 95000 | F45: 100000 | G45: 100000
B46: % price increase
B47: Day of working | C47: =D40 -> 357.7 | D47: =E40 -> 357.7 | E47: =F40 -> 357.7 | F47: =G40 -> 357.7 | G47: =F47 -> 357.7
...

Sheet WACC
A2: Risk free rate | B2: =W3 -> 0.042755 | I2: Ngày | J2: Lần cuối | K2: Lần cuối | M2: Return market | N2: Return PVD
A3: Equity risk prenium | B3: 0.0813 | I3: 21/05/2023 | J3: 1063.76 | K3: 23850 | T3: Ngày | U3: Lần cuối | W3: =AVERAGE(U4:U158)/100 -> 0.042755
A4: Beta | B4: =Q8 -> 1.0733333 | I4: 28/05/2023 | J4: 1090.84 | K4: 24300 | M4: =LN(J4/J3) -> 0.02513824 | N4: =LN(K4/K3) -> 0.018692133 | T4: 29/05/2026 | U4: 4.458
A5: Market capitalization | B5: 17232280000000 | I5: 45022 | J5: 1107.53 | K5: 23600 | M5: =LN(J5/J4) -> 0.015184269 | N5: =LN(K5/K4) -> -0.029229638 | T5: 28/05/2026 | U5: 4.457
A6: Share outstanding | B6: 555880006 | I6: 45236 | J6: 1115.22 | K6: 23850 | M6: =LN(J6/J5) -> 0.0069193843 | N6: =LN(K6/K5) -> 0.010537505 | T6: 27/05/2026 | U6: 4.388
A7: Debt | B7: =Debt!F6 -> 4409257786391 | I7: 18/06/2023 | J7: 1129.38 | K7: 24150 | M7: =LN(J7/J6) -> 0.012617115 | N7: =LN(K7/K6) -> 0.012500163 | P7: beta | Q7: =SLOPE(N4:N261,M4:M261) -> 1.1114468 | T7: 26/05/2026 | U7: 4.384
A8: Cost of equity | B8: =B2+B4*B3 -> 0.130017 | I8: 25/06/2023 | J8: 1120.18 | K8: 24500 | M8: =LN(J8/J7) -> -0.0081794229 | N8: =LN(K8/K7) -> 0.014388737 | P8: adjusted beta | Q8: =2/3*1.11+1/3 -> 1.0733333 | T8: 25/05/2026 | U8: 4.384
A9: Cost of debt | B9: =Debt!B8 -> 0.065 | I9: 44964 | J9: 1138.07 | K9: 24850 | M9: =LN(J9/J8) -> 0.015844459 | N9: =LN(K9/K8) -> 0.014184635 | T9: 22/05/2026 | U9: 4.384
A10: Total | B10: =B5+B7 -> 21641537786391 | I10: 45176 | J10: 1168.4 | K10: 25150 | M10: =LN(J10/J9) -> 0.026301446 | N10: =LN(K10/K9) -> 0.012000144 | T10: 21/05/2026 | U10: 4.384
A11: Weight of equity | B11: =B5/B10 -> 0.7962595 | I11: 16/07/2023 | J11: 1185.9 | K11: 25100 | M11: =LN(J11/J10) -> 0.014866688 | N11: =LN(K11/K10) -> -0.0019900504 | T11: 20/05/2026 | U11: 4.379
A12: Weight of debt | B12: =B7/B10 -> 0.2037405 | I12: 23/07/2023 | J12: 1207.67 | K12: 26450 | M12: =LN(J12/J11) -> 0.018190903 | N12: =LN(K12/K11) -> 0.052388312 | T12: 19/05/2026 | U12: 4.374
A13: Tax | B13: 0.2 | I13: 30/07/2023 | J13: 1225.98 | K13: 25850 | M13: =LN(J13/J12) -> 0.015047641 | N13: =LN(K13/K12) -> -0.022945557 | T13: 18/05/2026 | U13: 4.378
A14: WACC | B14: =B11*B8+B12*B9*(1-B13) -> 0.11412178 | I14: 45085 | J14: 1232.21 | K14: 25500 | M14: =LN(J14/J13) -> 0.005068781 | N14: =LN(K14/K13) -> -0.013632149 | T14: 15/05/2026 | U14: 4.375
I15: 13/08/2023 | J15: 1177.99 | K15: 23750 | M15: =LN(J15/J14) -> -0.044999709 | N15: =LN(K15/K14) -> -0.071095922 | T15: 14/05/2026 | U15: 4.375
I16: 20/08/2023 | J16: 1183.37 | K16: 24650 | M16: =LN(J16/J15) -> 0.004556704 | N16: =LN(K16/K15) -> 0.03719437 | T16: 13/05/2026 | U16: 4.371
I17: 27/08/2023 | J17: 1224.05 | K17: 25500 | M17: =LN(J17/J16) -> 0.033798733 | N17: =LN(K17/K16) -> 0.033901552 | T17: 46361 | U17: 4.371
I18: 44994 | J18: 1241.48 | K18: 26450 | M18: =LN(J18/J17) -> 0.014139183 | N18: =LN(K18/K17) -> 0.036577706 | T18: 46331 | U18: 4.37
I19: 45208 | J19: 1227.36 | K19: 27200 | M19: =LN(J19/J18) -> -0.011438695 | N19: =LN(K19/K18) -> 0.027960815 | T19: 46239 | U19: 4.372
I20: 17/09/2023 | J20: 1193.05 | K20: 25450 | M20: =LN(J20/J19) -> -0.028352468 | N20: =LN(K20/K19) -> -0.06650123 | T20: 46208 | U20: 4.373
I21: 24/09/2023 | J21: 1154.15 | K21: 25800 | M21: =LN(J21/J20) -> -0.033148911 | N21: =LN(K21/K20) -> 0.013658749 | T21: 46178 | U21: 4.372
I22: 44936 | J22: 1128.54 | K22: 25800 | M22: =LN(J22/J21) -> -0.02243938 | N22: =LN(K22/K21) -> 0 | T22: 46147 | U22: 4.365
I23: 45148 | J23: 1154.73 | K23: 28450 | M23: =LN(J23/J22) -> 0.022941788 | N23: =LN(K23/K22) -> 0.097773669 | T23: 46117 | U23: 4.349
I24: 15/10/2023 | J24: 1108.03 | K24: 28300 | M24: =LN(J24/J23) -> -0.041282887 | N24: =LN(K24/K23) -> -0.0052863559 | T24: 46027 | U24: 4.371
I25: 22/10/2023 | J25: 1060.62 | K25: 25800 | M25: =LN(J25/J24) -> -0.043730021 | N25: =LN(K25/K24) -> -0.092487313 | T25: 30/04/2026 | U25: 4.371
I26: 29/10/2023 | J26: 1076.78 | K26: 25750 | M26: =LN(J26/J25) -> 0.015121463 | N26: =LN(K26/K25) -> -0.0019398648 | T26: 29/04/2026 | U26: 4.371
I27: 45057 | J27: 1101.68 | K27: 26800 | M27: =LN(J27/J26) -> 0.022861181 | N27: =LN(K27/K26) -> 0.03996726 | T27: 28/04/2026 | U27: 4.366
I28: 45271 | J28: 1101.19 | K28: 26400 | M28: =LN(J28/J27) -> -0.00044487419 | N28: =LN(K28/K27) -> -0.015037877 | T28: 27/04/2026 | U28: 4.366
I29: 19/11/2023 | J29: 1095.61 | K29: 27000 | M29: =LN(J29/J28) -> -0.0050801275 | N29: =LN(K29/K28) -> 0.022472856 | T29: 24/04/2026 | U29: 4.366
I30: 26/11/2023 | J30: 1102.16 | K30: 28350 | M30: =LN(J30/J29) -> 0.005960605 | N30: =LN(K30/K29) -> 0.048790164 | T30: 23/04/2026 | U30: 4.368
I31: 44997 | J31: 1124.44 | K31: 28500 | M31: =LN(J31/J30) -> 0.020013243 | N31: =LN(K31/K30) -> 0.0052770571 | T31: 22/04/2026 | U31: 4.372
I32: 45211 | J32: 1102.3 | K32: 27000 | M32: =LN(J32/J31) -> -0.019886228 | N32: =LN(K32/K31) -> -0.054067221 | T32: 21/04/2026 | U32: 4.372
I33: 17/12/2023 | J33: 1103.06 | K33: 27800 | M33: =LN(J33/J32) -> 0.0006892299 | N33: =LN(K33/K32) -> 0.029199155 | T33: 20/04/2026 | U33: 4.372
I34: 24/12/2023 | J34: 1129.93 | K34: 28300 | M34: =LN(J34/J33) -> 0.024067548 | N34: =LN(K34/K33) -> 0.017825784 | T34: 17/04/2026 | U34: 4.356
I35: 31/12/2023 | J35: 1154.68 | K35: 27800 | M35: =LN(J35/J34) -> 0.021667565 | N35: =LN(K35/K34) -> -0.017825784 | T35: 16/04/2026 | U35: 4.355
I36: 45474 | J36: 1154.7 | K36: 26900 | M36: =LN(J36/J35) -> 1.7320666e-05 | N36: =LN(K36/K35) -> -0.032909734 | T36: 15/04/2026 | U36: 4.356
I37: 14/01/2024 | J37: 1181.5 | K37: 27350 | M37: =LN(J37/J36) -> 0.022944248 | N37: =LN(K37/K36) -> 0.016590242 | T37: 14/04/2026 | U37: 4.363
I38: 21/01/2024 | J38: 1175.67 | K38: 27650 | M38: =LN(J38/J37) -> -0.0049466198 | N38: =LN(K38/K37) -> 0.010909199 | T38: 13/04/2026 | U38: 4.368
I39: 28/01/2024 | J39: 1172.55 | K39: 27800 | M39: =LN(J39/J38) -> -0.0026573335 | N39: =LN(K39/K38) -> 0.0054102927 | T39: 46299 | U39: 4.377
I40: 45384 | J40: 1198.53 | K40: 28750 | M40: =LN(J40/J39) -> 0.021914942 | N40: =LN(K40/K39) -> 0.033601747 | T40: 46269 | U40: 4.363
I41: 45598 | J41: 1209.7 | K41: 28500 | M41: =LN(J41/J40) -> 0.0092765891 | N41: =LN(K41/K40) -> -0.00873368 | T41: 46238 | U41: 4.363
...

Sheet Firm Value
A1: Tax rate | B1: =WACC!B13 -> 0.2
A2: Wacc | B2: =WACC!B14 -> 0.11412178 | E2: 0 | F2: 1 | G2: 2 | H2: 3 | I2: 4 | J2: 5
A3: g | B3: 0.03 | E3: 2025 | F3: 2026 | G3: 2027 | H3: 2028 | I3: 2029 | J3: 2030
D4: EBIT | E4: =Forecasting!B9 -> 1577081290420 | F4: =Forecasting!C9 -> 1.9479926e+12 | G4: =Forecasting!D9 -> 2.2389592e+12 | H4: =Forecasting!E9 -> 2.5071848e+12 | I4: =Forecasting!F9 -> 2.872338e+12 | J4: =Forecasting!G9 -> 3.1367119e+12
D5: Depreciation | E5: =Depreciation!F4 -> 859603231390 | F5: =Depreciation!G4 -> 8.5390214e+11 | G5: =Depreciation!H4 -> 9.0695639e+11 | H5: =Depreciation!I4 -> 9.4462365e+11 | I5: =Depreciation!J4 -> 9.8514692e+11 | J5: =Depreciation!K4 -> 1.0286885e+12
D6: FC change | F6: =Forecasting!C30-Forecasting!B30 -> 1.3237163e+12 | G6: =Forecasting!D30-Forecasting!C30 -> 1.1471395e+12 | H6: =Forecasting!E30-Forecasting!D30 -> 5.9401895e+11 | I6: =Forecasting!F30-Forecasting!E30 -> 6.5663526e+11 | J6: =Forecasting!G30-Forecasting!F30 -> 7.2304069e+11
D7: WC | E7: =Forecasting!B25+Forecasting!B26-Forecasting!B37-Forecasting!B38 -> 1489546820392 | F7: =Forecasting!C25+Forecasting!C26-Forecasting!C37-Forecasting!C38 -> 2.0358677e+12 | G7: =Forecasting!D25+Forecasting!D26-Forecasting!D37-Forecasting!D38 -> 2.9520998e+12 | H7: =Forecasting!E25+Forecasting!E26-Forecasting!E37-Forecasting!E38 -> 3.4836853e+12 | I7: =Forecasting!F25+Forecasting!F26-Forecasting!F37-Forecasting!F38 -> 3.9299251e+12 | J7: =Forecasting!G25+Forecasting!G26-Forecasting!G37-Forecasting!G38 -> 4.0554758e+12
D8: WC change | F8: =F7-E7 -> 5.4632086e+11 | G8: =G7-F7 -> 9.1623211e+11 | H8: =H7-G7 -> 5.315855e+11 | I8: =I7-H7 -> 4.4623981e+11 | J8: =J7-I7 -> 1.2555067e+11
D9: FCFF | F9: =F4*(1-$B$1)+F5-F6-F8 -> 5.4225911e+11 | G9: =G4*(1-$B$1)+G5-G6-G8 -> 6.3475208e+11 | H9: =H4*(1-$B$1)+H5-H6-H8 -> 1.824767e+12 | I9: =I4*(1-$B$1)+I5-I6-I8 -> 2.1801423e+12 | J9: =J4*(1-$B$1)+J5-J6-J8 -> 2.6894666e+12
D10: Discounted FCFF | F10: =F9/((1+$B$2)^F2) -> 4.867144e+11 | G10: =G9/((1+$B$2)^G2) -> 5.1137419e+11 | H10: =H9/((1+$B$2)^H2) -> 1.3195001e+12 | I10: =I9/((1+$B$2)^I2) -> 1.4149926e+12 | J10: =J9/((1+$B$2)^J2) -> 1.5667613e+12
D11: Terminal value | J11: =J9*(1+B3)/(B2-B3) -> 3.2930244e+13
D12: Discounted TV | J12: =J11/((1+B2)^J2) -> 1.9183667e+13
D13: Value of firm | E13: =SUM(F10:J10,J12) -> 2.448301e+13

Sheet Absolute Method
B2: FCFF
B3: Value of operations | C3: ='Firm Value'!E13 -> 2.448301e+13
B4: Plus value non-oprating assests | C4: =Forecasting!B24+Forecasting!B23 -> 2510230067402
B5: Less: Value of debt | C5: =Debt!F6 -> 4409257786391
B6: Value of equity | C6: =SUM(C3:C4)-C5-Forecasting!B53 -> 2.2326756e+13
B7: Divide by number of shares | C7: =WACC!B6 -> 555880006
B8: Price per share | C8: =C6/C7 -> 40164.704

Sheet Relative Method
B4: EV/EBITDA | C4: =Peer!O23 -> 8.4379276
B5: P/B | C5: =Peer!O24 -> 1.0527486
C10: EV/EBITDA | D10: P/B
B11: EV | C11: =Forecasting!J7*C4 -> 2.3642185e+13
B12: Short-term debt | C12: =Forecasting!B39 -> 821033901691
B13: Long-term debt | C13: =Forecasting!B42 -> 3588223884700
B14: Cash and cash equivalent | C14: =Forecasting!B23 -> 1821273980243
B15: Equity | C15: =C11-C12-C13+C14 -> 2.1054201e+13 | D15: =Forecasting!B46*C5 -> 1.8000198e+13
B16: Share outstanding | C16: =WACC!B6 -> 555880006 | D16: =C16 -> 555880006
B17: Price per share | C17: =C15/C16 -> 37875.443 | D17: =D15/D16 -> 32381.445
B18: Weight | C18: 0.7 | D18: 0.3
B19: Price per share | C19: =SUMPRODUCT(C17:D17,C18:D18) -> 36227.243

Sheet Peer
B1: PVD (VND) | D1: Velesto (USD) | E1: Borr (USD) | F1: Seadrill (USD) | K1: PVD (VND) | L1: Velesto (USD) | M1: Borr (USD) | N1: Seadrill (USD)
B2: 2026 | C2: 2025 | D2: 2025 | E2: 2025 | F2: 2025 | K2: 2024 | L2: 2024 | M2: 2024 | N2: 2024
A3: Market capitaliztion | B3: 17232280000000 | C3: =WACC!B5 -> 17232280000000 | D3: 2603000000 | E3: 1880000000 | F3: 3079000000 | J3: Market capitaliztion | K3: 17232280000000 | L3: 2603000000 | M3: 1880000000 | N3: 3079000000
A4: Short-term debt | B4: =Forecasting!C39 -> 9.3695567e+11 | C4: =Forecasting!B39 -> 821033901691 | D4: 117688000 | E4: 1.293e+08 | F4: 313000000 | J4: Short-term debt | K4: ='Historical Data'!E56 -> 507298751244 | L4: 179558000 | M4: 118100000 | N4: 383000000
A5: Long-term debt | B5: =Forecasting!C42 -> 2.9618615e+12 | C5: =Forecasting!B42 -> 3588223884700 | D5: 6584000 | E5: 2021000000 | F5: 613000000 | J5: Long-term debt | K5: ='Historical Data'!E59 -> 2541390152379 | L5: 2595000 | M5: 1992500000 | N5: 610000000
A6: Cash and cash equivalent | B6: =Forecasting!C23 -> 1.8508872e+12 | C6: =Forecasting!B23 -> 1821273980243 | D6: 261419000 | E6: 379700000 | F6: 339000000 | J6: Cash and cash equivalent | K6: ='Historical Data'!E34 -> 2203268274194 | L6: 247522000 | M6: 61600000 | N6: 478000000
A7: EV | B7: =SUM(B3,B4:B5)-B6 -> 1.928021e+13 | C7: =SUM(C3,C4:C5)-C6 -> 19820263806148 | D7: =SUM(D3,D4:D5)-D6 -> 2465853000 | E7: =SUM(E3,E4:E5)-E6 -> 3650600000 | F7: =SUM(F3,F4:F5)-F6 -> 3666000000 | J7: EV | K7: =SUM(K3,K4:K5)-K6 -> 18077700629429 | L7: =SUM(L3,L4:L5)-L6 -> 2537631000 | M7: =SUM(M3,M4:M5)-M6 -> 3929000000 | N7: =SUM(N3,N4:N5)-N6 -> 3594000000
A8: EBIT | B8: =Forecasting!C9 -> 1.9479926e+12 | C8: =Forecasting!B9 -> 1577081290420 | D8: 239603000 | E8: 322100000 | F8: 47000000 | J8: EBIT | K8: ='Historical Data'!E20 -> 1175049571275 | L8: 293957000 | M8: 374200000 | N8: 412000000
A9: Depreciation and armotization | B9: =Forecasting!J6 -> 8.5390214e+11 | C9: ='Historical Data'!F19 -> 859603231390 | D9: 207381000 | E9: 148000000 | F9: 238000000 | J9: Depreciation and armotization | K9: ='Historical Data'!E19 -> 883531324989 | L9: 245667000 | M9: 1.312e+08 | N9: 168000000
A10: EBITDA | B10: =SUM(B8:B9) -> 2.8018948e+12 | C10: =SUM(C8:C9) -> 2436684521810 | D10: =SUM(D8:D9) -> 446984000 | E10: =SUM(E8:E9) -> 470100000 | F10: =SUM(F8:F9) -> 285000000 | J10: EBITDA | K10: =SUM(K8:K9) -> 2058580896264 | L10: =SUM(L8:L9) -> 539624000 | M10: =SUM(M8:M9) -> 505400000 | N10: =SUM(N8:N9) -> 580000000
A11: Net income after tax | B11: =Forecasting!C13 -> 1.3191913e+12 | C11: =Forecasting!B13 -> 1051572991932 | D11: 202176000 | E11: 45000000 | F11: -51000000 | J11: Net income after tax | K11: ='Historical Data'!E25 -> 697970710425 | L11: 207706000 | M11: 82100000 | N11: 446000000
A12: Equity | B12: =Forecasting!C46 -> 1.986648e+13 | C12: =Forecasting!B46 -> 17098286949122 | D12: 2392689000 | E12: 1222600000 | F12: 2858000000 | J12: Equity | K12: ='Historical Data'!E62 -> 16052342324403 | L12: 2571203000 | M12: 993300000 | N12: 2918000000
A13: Average shareholder equity | B13: =AVERAGE(Forecasting!B46:C46) -> 1.8482384e+13 | C13: ='Additional Data'!G16 -> 1.6575315e+13 | D13: 2481946000 | E13: 1.10795e+09 | F13: 2888000000 | J13: Average shareholder equity | K13: ='Additional Data'!F16 -> 1.547525e+13 | L13: 2523305500 | M13: 988650000 | N13: 2950500000
A14: Average total asset | B14: =AVERAGE(Forecasting!B34:C34) -> 2.9494124e+13 | C14: ='Additional Data'!G14 -> 2.596221e+13 | D14: 2952216500 | E14: 3522600000 | F14: 4051500000 | J14: Average total asset | K14: ='Additional Data'!F14 -> 2.2623703e+13 | L14: 3089477000 | M14: 3522600000 | N14: 4187000000
A15: EV/EBITDA | B15: =B7/B10 -> 6.8811328 | C15: =C7/C10 -> 8.1341116 | D15: =D7/D10 -> 5.5166471 | E15: =E7/E10 -> 7.7655818 | F15: =F7/F10 -> 12.863158 | J15: EV/EBITDA | K15: =K7/K10 -> 8.7816324 | L15: =L7/L10 -> 4.7025911 | M15: =M7/M10 -> 7.7740404 | N15: =N7/N10 -> 6.1965517
A16: P/B | B16: =B3/B12 -> 0.86740478 | C16: =C3/C12 -> 1.0078366 | D16: =D3/D12 -> 1.0878973 | E16: =E3/E12 -> 1.5377065 | F16: =F3/F12 -> 1.0773268 | J16: P/B | K16: =K3/K12 -> 1.0735056 | L16: =L3/L12 -> 1.0123666 | M16: =M3/M12 -> 1.892681 | N16: =N3/N12 -> 1.0551748
A17: P/E | B17: =B3/B11 -> 13.062761 | C17: =C3/C11 -> 16.387146 | D17: =D3/D11 -> 12.874921 | E17: =E3/E11 -> 41.777778 | F17: =F3/F11 -> -60.372549 | J17: P/E | K17: =K3/K11 -> 24.689116 | L17: =L3/L11 -> 12.532137 | M17: =M3/M11 -> 22.898904 | N17: =N3/N11 -> 6.9035874
A18: ROA | B18: =B11/B14 -> 0.044727257 | C18: =C11/C14 -> 0.040503986 | D18: =D11/D14 -> 0.068482782 | E18: =E11/E14 -> 0.012774655 | F18: =F11/F14 -> -0.01258793 | J18: ROA | K18: =K11/K14 -> 0.030851303 | L18: =L11/L14 -> 0.067230149 | M18: =M11/M14 -> 0.023306648 | N18: =N11/N14 -> 0.10652018
A19: ROE | B19: =B11/B13 -> 0.071375604 | C19: =C11/C13 -> 0.063442113 | D19: =D11/D13 -> 0.081458662 | E19: =E11/E13 -> 0.040615551 | F19: =F11/F13 -> -0.01765928 | J19: ROE | K19: =K11/K13 -> 0.045102387 | L19: =L11/L13 -> 0.082315043 | M19: =M11/M13 -> 0.083042533 | N19: =N11/N13 -> 0.15116082
C22: PVD (VND) | D22: Velesto (USD) | E22: Borr (USD) | F22: Seadrill (USD) | K22: PVD (VND) | L22: Velesto (USD) | M22: Borr (USD) | N22: Seadrill (USD) | O22: Average
C23: 2023 | D23: 2023 | E23: 2023 | F23: 2023 | J23: EV/EBITDA | K23: =AVERAGE(B15,C15,K15,C36) -> 8.5428182 | L23: =AVERAGE(D15,L15,D36) -> 5.9973003 | M23: =AVERAGE(E15,M15,E36) -> 8.333037 | N23: =AVERAGE(F15,N15,F36) -> 8.6438701 | O23: =MEDIAN(K23:N23) -> 8.4379276
A24: Market capitaliztion | C24: 17232280000000 | D24: 2603000000 | E24: 1880000000 | F24: 3079000000 | J24: P/B | K24: =AVERAGE(B16,C16,K16,C37) -> 1.0263547 | L24: =AVERAGE(D16,L16,D37) -> 1.0506026 | M24: =AVERAGE(E16,M16,E37) -> 1.7803189 | N24: =AVERAGE(F16,N16,F37) -> 1.0548946 | O24: =MEDIAN(K24:N24) -> 1.0527486
A25: Short-term debt | C25: ='Historical Data'!D56 -> 553352813440 | D25: 118385000 | E25: 82900000 | F25: 336000000 | J25: P/E | K25: =AVERAGE(B17,C17,K17,C38) -> 21.425829 | L25: =AVERAGE(D17,L17,D38) -> 17.187097 | M25: =AVERAGE(E17,M17,E38) -> 49.914852 | N25: =AVERAGE(F17,N17,F38) -> -14.401876 | O25: =MEDIAN(K25:M25) -> 21.425829
A26: Long-term debt | C26: ='Historical Data'!D59 -> 2787681809360 | D26: 247712000 | E26: 1618800000 | F26: 608000000 | J26: ROA | K26: =AVERAGE(B18,C18,K18,C39) -> 0.03546823 | L26: =AVERAGE(D18,L18,D39) -> 0.055944425 | M26: =AVERAGE(E18,M18,E39) -> 0.01444963 | N26: =AVERAGE(F18,N18,F39) -> 0.059804838 | O26: =AVERAGE(K26:N26) -> 0.041416781
A27: Cash and cash equivalent | C27: ='Historical Data'!D34 -> 2256047157280 | D27: 132215000 | E27: 102500000 | F27: 697000000 | J27: ROE | K27: =AVERAGE(B19,C19,K19,C40) -> 0.054400402 | L27: =AVERAGE(D19,L19,D40) -> 0.068538887 | M27: =AVERAGE(E19,M19,E40) -> 0.049048745 | N27: =AVERAGE(F19,N19,F40) -> 0.087189948 | O27: =AVERAGE(K27:N27) -> 0.064794495
A28: EV | C28: =SUM(C24,C25:C26)-C27 -> 18317267465520 | D28: =SUM(D24,D25:D26)-D27 -> 2836882000 | E28: =SUM(E24,E25:E26)-E27 -> 3479200000 | F28: =SUM(F24,F25:F26)-F27 -> 3326000000
A29: EBIT | C29: ='Historical Data'!D20 -> 908879240802 | D29: 163043000 | E29: 250400000 | F29: 329000000
A30: Depreciation and armotization | C30: ='Historical Data'!D19 -> 856743293328 | D30: 201939000 | E30: 117400000 | F30: 155000000
A31: EBITDA | C31: =SUM(C29:C30) -> 1765622534130 | D31: =SUM(D29:D30) -> 364982000 | E31: =SUM(E29:E30) -> 367800000 | F31: =SUM(F29:F30) -> 484000000
A32: Net income after tax | C32: ='Historical Data'!D25 -> 545942180784 | D32: 99525000 | E32: 22100000 | F32: 300000000
A33: Equity | C33: ='Historical Data'!D63 -> 14898157540000 | D33: 2475408000 | E33: 984000000 | F33: 2983000000
A34: Average shareholder equity | C34: ='Additional Data'!E16 -> 14488333421565 | D34: 2378536500 | E34: 940900000 | F34: 2342500000
A35: Average total asset | C35: ='Additional Data'!E14 -> 21168447449535 | D35: 3098503500 | E35: 3.0409e+09 | F35: 3509500000
A36: EV/EBITDA | C36: =C28/C31 -> 10.374396 | D36: =D28/D31 -> 7.7726628 | E36: =E28/E31 -> 9.4594889 | F36: =F28/F31 -> 6.8719008
A37: P/B | C37: =C24/C33 -> 1.1566719 | D37: =D24/D33 -> 1.0515438 | E37: =E24/E33 -> 1.9105691 | F37: =F24/F33 -> 1.0321824
A38: P/E | C38: =C24/C32 -> 31.564295 | D38: =D24/D32 -> 26.154233 | E38: =E24/E32 -> 85.067873 | F38: =F24/F32 -> 10.263333
A39: ROA | C39: =C32/C35 -> 0.025790374 | D39: =D32/D35 -> 0.032120345 | E39: =E32/E35 -> 0.0072675853 | F39: =F32/F35 -> 0.085482262
A40: ROE | C40: =C32/C34 -> 0.037681503 | D40: =D32/D34 -> 0.041842957 | E40: =E32/E34 -> 0.02348815 | F40: =F32/F34 -> 0.1280683

Sheet Sensitivity Analysis
A1: ='Firm Value'!B2 -> 0.11412178
A2: ='Firm Value'!B3 -> 0.03
A3: ='Absolute Method'!C8 -> 40164.704 | C3: Sensitive Analysis
E4: Sale Growth
D5: =('Firm Value'!F9/(1+A1)^1+'Firm Value'!G9/(1+A1)^2+'Firm Value'!H9/(1+A1)^3+'Firm Value'!I9/(1+A1)^4+'Firm Value'!J9/(1+A1)^5+'Firm Value'!J9*(1+A2)/(A1-A2)/(1+A1)^5+'Absolute Method'!C4-'Absolute Method'!C5-Forecasting!B53)/'Absolute Method'!C7 -> 40164.704 | E5: =F5-1% -> 0.01 | F5: =G5-1% -> 0.02 | G5: ='Firm Value'!B3 -> 0.03 | H5: =G5+1% -> 0.04 | I5: =H5+1% -> 0.05
C6: WACC | D6: =D7-1% -> 0.094121777 | E6: 43343.675 | F6: 48758.298 | G6: 55861.776 | H6: 65590.253 | I6: 79728.56
D7: =D8-1% -> 0.10412178 | E7: 37607.093 | F7: 41718.766 | G7: 46939.878 | H7: 53789.487 | I7: 63170.281
D8: ='Firm Value'!B2 -> 0.11412178 | E8: 32994.451 | F8: 36198.675 | G8: 40164.704 | H8: 45200.871 | I8: 51807.853
D9: =D8+1% -> 0.12412178 | E9: 29209.402 | F9: 31759.293 | G9: 34851.011 | H9: 38677.788 | I9: 43537.129
D10: =D9+1% -> 0.13412178 | E10: 26051.143 | F10: 28115.714 | G10: 30576.854 | H10: 33560.962 | I10: 37254.545

Sheet Financial Analysis
A1: Key Financial Metrics
B2: 2021 | C2: 2022 | D2: 2023 | E2: 2024 | F2: 2025 | G2: 2026 | H2: 2027 | I2: 2028 | J2: 2029 | K2: 2030
A3: Net Revenue | B3: ='Historical Data'!B3 -> 3995471964670 | C3: ='Historical Data'!C3 -> 5431604613820 | D3: ='Historical Data'!D3 -> 5804412484923 | E3: ='Historical Data'!E3 -> 9288059307546 | F3: ='Historical Data'!F3 -> 10896989276040 | G3: =Forecasting!C2 -> 1.2339248e+13 | H3: =Forecasting!D2 -> 1.4863539e+13 | I3: =Forecasting!E2 -> 1.62994e+13 | J3: =Forecasting!F2 -> 1.7615176e+13 | K3: =Forecasting!G2 -> 1.8137279e+13 | M3: =(K3/F3)^(1/5)-1 -> 0.10726895 | Q3: 2021 | R3: 2022 | S3: 2023 | T3: 2024 | U3: 2025 | V3: 2026 | W3: 2027 | X3: 2028 | Y3: 2029 | Z3: 2030
A4: Net Revenue growth (%) | C4: =(C3-B3)/B3 -> 0.35944005 | D4: =(D3-C3)/C3 -> 0.068636784 | E4: =(E3-D3)/D3 -> 0.60017217 | F4: =(F3-E3)/E3 -> 0.17322563 | G4: =(G3-F3)/F3 -> 0.13235388 | H4: =(H3-G3)/G3 -> 0.20457411 | I4: =(I3-H3)/H3 -> 0.096602928 | J4: =(J3-I3)/I3 -> 0.080725414 | K4: =(K3-J3)/J3 -> 0.02963939 | P4: Net Revenue | Q4: =B3/1000000000 -> 3995.472 | R4: =C3/1000000000 -> 5431.6046 | S4: =D3/1000000000 -> 5804.4125 | T4: =E3/1000000000 -> 9288.0593 | U4: =F3/1000000000 -> 10896.989 | V4: =G3/1000000000 -> 12339.248 | W4: =H3/1000000000 -> 14863.539 | X4: =I3/1000000000 -> 16299.4 | ... Z4: =K3/1000000000 -> 18137.279
A5: Dupont Analysis | P5: Net Revenue growth (%) | R5: 0.35944005 | S5: 0.068636784 | T5: 0.60017217 | U5: 0.17322563 | V5: 0.13235388 | W5: 0.20457411 | X5: 0.096602928 | Y5: 0.080725414 | Z5: 0.02963939
A6: Gross margin (%) | B6: ='Historical Data'!B11/'Historical Data'!B3 -> 0.092915293 | C6: ='Historical Data'!C11/'Historical Data'!C3 -> 0.10630879 | D6: ='Historical Data'!D11/'Historical Data'!D3 -> 0.224914 | E6: ='Historical Data'!E11/'Historical Data'!E3 -> 0.18886365 | F6: ='Historical Data'!F11/'Historical Data'!F3 -> 0.19068391 | G6: =Forecasting!C5/Forecasting!C2 -> 0.23765071 | H6: =Forecasting!D5/Forecasting!D2 -> 0.23871904 | I6: =Forecasting!E5/Forecasting!E2 -> 0.29511088 | J6: =Forecasting!F5/Forecasting!F2 -> 0.30674892 | K6: =Forecasting!G5/Forecasting!G2 -> 0.31700844 | Q6: 3995.472 | R6: 5431.6046 | S6: 5804.4125 | T6: 9288.0593 | U6: 10896.989 | V6: 12339.248 | W6: 14863.539 | X6: 16299.4 | Y6: 17615.176 | Z6: 18137.279
A7: Operating margin (%) | B7: ='Historical Data'!B20/'Historical Data'!B3 -> 0.04299438 | C7: ='Historical Data'!C20/'Historical Data'!C3 -> 0.0054338975 | D7: ='Historical Data'!D20/'Historical Data'!D3 -> 0.15658419 | E7: ='Historical Data'!E20/'Historical Data'!E3 -> 0.12651185 | F7: ='Historical Data'!F20/'Historical Data'!F3 -> 0.14472633 | G7: =Forecasting!C9/Forecasting!C2 -> 0.15786964 | H7: =Forecasting!D9/Forecasting!D2 -> 0.15063433 | I7: =Forecasting!E9/Forecasting!E2 -> 0.15382068 | J7: =Forecasting!F9/Forecasting!F2 -> 0.16306042 | K7: =Forecasting!G9/Forecasting!G2 -> 0.1729428
A8: Net margin (%) | B8: ='Historical Data'!B25/'Historical Data'!B3 -> 0.0092029096 | C8: ='Historical Data'!C25/'Historical Data'!C3 -> -0.028510256 | D8: ='Historical Data'!D25/'Historical Data'!D3 -> 0.094056407 | E8: ='Historical Data'!E25/'Historical Data'!E3 -> 0.075147099 | F8: ='Historical Data'!F25/'Historical Data'!F3 -> 0.096501241 | G8: =Forecasting!C13/Forecasting!C2 -> 0.10691018 | H8: =Forecasting!D13/Forecasting!D2 -> 0.10413505 | I8: =Forecasting!E13/Forecasting!E2 -> 0.10584565 | J8: =Forecasting!F13/Forecasting!F2 -> 0.12051803 | K8: =Forecasting!G13/Forecasting!G2 -> 0.12928134
A9: Asset Turnover (times) | B9: =B3/'Additional Data'!C14 -> 0.19200972 | C9: =C3/'Additional Data'!D14 -> 0.26198345 | D9: =D3/'Additional Data'!E14 -> 0.27420114 | E9: =E3/'Additional Data'!F14 -> 0.41054549 | F9: =F3/'Additional Data'!G14 -> 0.41972502 | G9: =G3/Forecasting!C34 -> 0.40221308 | H9: =H3/Forecasting!D34 -> 0.43846903 | I9: =I3/Forecasting!E34 -> 0.48852951 | J9: =J3/Forecasting!F34 -> 0.49396123 | K9: =K3/Forecasting!G34 -> 0.47341467 | P9: 2021 | Q9: 3995.472
A10: Financial Leverage (times) | B10: ='Additional Data'!C14/'Additional Data'!C16 -> 1.4930757 | C10: ='Additional Data'!D14/'Additional Data'!D16 -> 1.4856724 | D10: ='Additional Data'!E14/'Additional Data'!E16 -> 1.4610685 | E10: ='Additional Data'!F14/'Additional Data'!F16 -> 1.4619281 | F10: ='Additional Data'!G14/'Additional Data'!G16 -> 1.5663178 | G10: =Forecasting!C34/Forecasting!C46 -> 1.5442286 | H10: =Forecasting!D34/Forecasting!D46 -> 1.4565413 | I10: =Forecasting!E34/Forecasting!E46 -> 1.3173341 | J10: =Forecasting!F34/Forecasting!F46 -> 1.2931242 | K10: =Forecasting!G34/Forecasting!G46 -> 1.2754519 | P10: 2022 | Q10: 5431.6046 | S10: 0.35944005
A11: Return on Asset (%) | B11: ='Historical Data'!B25/'Additional Data'!C14 -> 0.0017670481 | C11: ='Historical Data'!C25/'Additional Data'!D14 -> -0.0074692154 | D11: ='Historical Data'!D25/'Additional Data'!E14 -> 0.025790374 | E11: ='Historical Data'!E25/'Additional Data'!F14 -> 0.030851303 | F11: ='Historical Data'!F25/'Additional Data'!G14 -> 0.040503986 | G11: =Forecasting!C13/Forecasting!C34 -> 0.043000674 | H11: =Forecasting!D13/Forecasting!D34 -> 0.045659994 | I11: =Forecasting!E13/Forecasting!E34 -> 0.051708722 | J11: =Forecasting!F13/Forecasting!F34 -> 0.059531232 | K11: =Forecasting!G13/Forecasting!G34 -> 0.061203683 | P11: 2023 | Q11: 5804.4125 | S11: 0.068636784
